<mujoco model="unnamed_model">
  <compiler angle="radian"/>
  <default>
    <default class="/"/>
    <default class="xarm6/">
      <default class="xarm6/xarm6">
        <joint axis="0 0 1" range="-6.2831900000000003 6.2831900000000003" frictionloss="1"/>
        <geom type="mesh" material="xarm6/white"/>
        <site group="4" rgba="1 0 0 1" size="0.001"/>
        <general ctrlrange="-6.2831900000000003 6.2831900000000003" biastype="affine"/>
        <default class="xarm6/size1">
          <joint damping="1"/>
          <general forcerange="-50 50" gainprm="1500" biasprm="0 -1500 -150"/>
        </default>
        <default class="xarm6/size2">
          <joint damping="1"/>
          <general forcerange="-32 32" gainprm="1000" biasprm="0 -1000 -100"/>
        </default>
        <default class="xarm6/size3">
          <joint damping="1"/>
          <general forcerange="-20 20" gainprm="800" biasprm="0 -800 -80"/>
        </default>
      </default>
    </default>
  </default>
  <asset>
    <material name="xarm6/white" class="xarm6/" rgba="1 1 1 1"/>
    <material name="xarm6/gray" class="xarm6/" rgba="0.753 0.753 0.753 1"/>
    <material name="xarm6/black" class="xarm6/" rgba="0.14899999999999999 0.14899999999999999 0.14899999999999999 1"/>
    <mesh name="xarm6/link_base" class="xarm6/" file="link_base-49c479141462a321aefb5d4b6fd34833caa474c7.stl"/>
    <mesh name="xarm6/link1" class="xarm6/" file="link1-57c408f3a98cfa635dc60299c03e09da71510788.stl"/>
    <mesh name="xarm6/link2" class="xarm6/" file="link2-6ec04b4c8ae94dea2e95239036d7432b886669af.stl"/>
    <mesh name="xarm6/link3" class="xarm6/" file="link3-e0226bbcb039c219df1b92f77fa0d6ca2b5a0d3d.stl"/>
    <mesh name="xarm6/link4" class="xarm6/" file="link4-b3637ec9841e4965b0a361d4540f8d9038a6523f.stl"/>
    <mesh name="xarm6/link5" class="xarm6/" file="link5-ba029c711717f9b57a2d1e582b3eb051bd6f8da7.stl"/>
    <mesh name="xarm6/link6" class="xarm6/" file="link6-50f8bb02f82e5ac05af8fe52c738d9348852e615.stl"/>
    <mesh name="xarm6/end_tool" class="xarm6/" file="end_tool-fba88989e12d718c4e6776399e40b7df4c85f363.stl"/>
  </asset>
  <worldbody>
    <body name="xarm6/">
      <body name="xarm6/link_base" childclass="xarm6/xarm6" pos="0 0 0">
        <inertial pos="0 0 0.09103" quat="0.98106499999999996 0.00074722799999999995 -0.0021865999999999999 -0.193666" mass="2.7000000000000002" diaginertia="0.0049502399999999998 0.0049403099999999998 0.00221894"/>
        <geom name="xarm6//unnamed_geom_0" contype="0" conaffinity="0" group="1" density="0" mesh="xarm6/link_base"/>
        <body name="xarm6/link1" pos="0 0 0.26700000000000002">
          <inertial pos="0.00022000000000000001 0.029510000000000002 -0.0124" quat="0.97613899999999998 -0.21607799999999999 -0.0038731199999999999 -0.021167700000000001" mass="2.3814000000000002" diaginertia="0.0058569700000000004 0.0054443399999999998 0.0031231499999999999"/>
          <joint name="xarm6/joint1" class="xarm6/size1" pos="0 0 0"/>
          <geom name="xarm6//unnamed_geom_1" contype="0" conaffinity="0" group="1" density="0" mesh="xarm6/link1"/>
          <body name="xarm6/link2" quat="0.70710499999999998 -0.70710799999999996 0 0">
            <inertial pos="0.038809999999999997 -0.22783 0.034959999999999998" quat="0.63530500000000001 0.753023 0.17097599999999999 -0.010531" mass="2.2675000000000001" diaginertia="0.0294477 0.0281783 0.0038344899999999999"/>
            <joint name="xarm6/joint2" class="xarm6/size1" pos="0 0 0"/>
            <geom name="xarm6//unnamed_geom_2" contype="0" conaffinity="0" group="1" density="0" mesh="xarm6/link2"/>
            <body name="xarm6/link3" pos="0.053499999999999999 -0.28449999999999998 0">
              <inertial pos="0.07041 0.11631 0.010699999999999999" quat="0.84583799999999998 0.425539 -0.29317900000000002 0.13236899999999999" mass="1.875" diaginertia="0.0071413199999999996 0.0069947100000000003 0.0019675299999999999"/>
              <joint name="xarm6/joint3" class="xarm6/size2" pos="0 0 0"/>
              <geom name="xarm6//unnamed_geom_3" contype="0" conaffinity="0" group="1" density="0" mesh="xarm6/link3"/>
              <body name="xarm6/link4" pos="0.077499999999999999 0.34250000000000003 0" quat="0.70710499999999998 -0.70710799999999996 0 0">
                <inertial pos="-0.00018000000000000001 0.017979999999999999 -0.02291" quat="0.99929000000000001 -0.036970200000000002 0.00179434 -0.0070117399999999998" mass="1.3191999999999999" diaginertia="0.0048961400000000002 0.0044740300000000004 0.00132609"/>
                <joint name="xarm6/joint4" class="xarm6/size2" pos="0 0 0"/>
                <geom name="xarm6//unnamed_geom_4" contype="0" conaffinity="0" group="1" density="0" mesh="xarm6/link4"/>
                <body name="xarm6/link5" quat="0.70710499999999998 0.70710799999999996 0 0">
                  <inertial pos="0.065100000000000005 0.030960000000000001 0.00315" quat="-0.22300800000000001 0.77130900000000002 0.16027 0.57416299999999998" mass="1.3385400000000001" diaginertia="0.0024182399999999999 0.0021336699999999998 0.00108731"/>
                  <joint name="xarm6/joint5" class="xarm6/size2" pos="0 0 0"/>
                  <geom name="xarm6//unnamed_geom_5" contype="0" conaffinity="0" group="1" density="0" mesh="xarm6/link5"/>
                  <body name="xarm6/link6" pos="0.075999999999999998 0.097000000000000003 0" quat="0.70710499999999998 -0.70710799999999996 0 0">
                    <inertial pos="0 -0.00677 -0.01098" quat="0.48761199999999999 0.51208799999999999 -0.51208799999999999 0.48761199999999999" mass="0.17000000000000001" diaginertia="0.00013217599999999999 9.2999999999999997e-05 5.8523600000000003e-05"/>
                    <joint name="xarm6/joint6" class="xarm6/size3" pos="0 0 0"/>
                    <geom name="xarm6//unnamed_geom_6" contype="0" conaffinity="0" group="1" material="xarm6/gray" density="0" mesh="xarm6/end_tool"/>
                    <body name="xarm6/link_eef"/>
                  </body>
                </body>
              </body>
            </body>
          </body>
        </body>
      </body>
    </body>
  </worldbody>
  <actuator>
    <general name="xarm6/act1" class="xarm6/size1" joint="xarm6/joint1"/>
    <general name="xarm6/act2" class="xarm6/size1" ctrlrange="-2.0590000000000002 2.0943999999999998" joint="xarm6/joint2"/>
    <general name="xarm6/act3" class="xarm6/size2" ctrlrange="-3.927 0.19198000000000001" joint="xarm6/joint3"/>
    <general name="xarm6/act4" class="xarm6/size2" joint="xarm6/joint4"/>
    <general name="xarm6/act5" class="xarm6/size2" ctrlrange="-1.6929700000000001 3.1415899999999999" joint="xarm6/joint5"/>
    <general name="xarm6/act6" class="xarm6/size3" joint="xarm6/joint6"/>
  </actuator>
</mujoco>
